Workbook
Name Metas_DB: #REF!
Name Metas_Distribuidor: #REF!
Name Metas_GD: #REF!
Name Metas_Geral: #REF!
Name Metas_Hemocentro: #REF!
Name Metas_Indústria: #REF!
Name Metas_Inst: #REF!
Name Metas_Interno: #REF!
Name Metas_LabCorp: #REF!
Name Metas_LPC: #REF!

Sheet FatoOrçamento
A1: Ano | B1: Mês | C1: Tipo_de_despesa | D1: Vl_Planejado | E1: Centro de Custo
A2: 2025 | B2: 1 | C2: ALIMENTAÇÃO | D2: 8000 | E2: COMERCIAL
A3: 2025 | B3: 2 | C3: ALIMENTAÇÃO | D3: 8000 | E3: COMERCIAL
A4: 2025 | B4: 3 | C4: ALIMENTAÇÃO | D4: 8000 | E4: COMERCIAL
A5: 2025 | B5: 4 | C5: ALIMENTAÇÃO | D5: 8000 | E5: COMERCIAL
A6: 2025 | B6: 5 | C6: ALIMENTAÇÃO | D6: 8000 | E6: COMERCIAL
A7: 2025 | B7: 6 | C7: ALIMENTAÇÃO | D7: 8000 | E7: COMERCIAL
A8: 2025 | B8: 7 | C8: ALIMENTAÇÃO | D8: 8000 | E8: COMERCIAL
A9: 2025 | B9: 8 | C9: ALIMENTAÇÃO | D9: 8000 | E9: COMERCIAL
A10: 2025 | B10: 9 | C10: ALIMENTAÇÃO | D10: 8000 | E10: COMERCIAL
A11: 2025 | B11: 10 | C11: ALIMENTAÇÃO | D11: 8000 | E11: COMERCIAL
A12: 2025 | B12: 11 | C12: ALIMENTAÇÃO | D12: 8000 | E12: COMERCIAL
A13: 2025 | B13: 12 | C13: ALIMENTAÇÃO | D13: 8000 | E13: COMERCIAL
... A769: 2026 | B769: 12 | C769: PEDÁGIO | D769: 0 | E769: SUPRIMENTOS

Sheet dimTipoDespesa
A1: DS_TIPO_DESP_VIAGEM | B1: Ajustada
A2: AG1 HOSPEDAGEM | B2: HOSPEDAGEM
A3: AG1 LOCAÇÃO | B3: LOCAÇÃO
A4: AG1 PASSAGEM | B4: PASSAGEM
A5: ALIMENTAÇÃO - DNH | B5: ALIMENTAÇÃO
A6: ALIMENTAÇÃO - VISA/MASTERCARD | B6: ALIMENTAÇÃO
A7: ALIMENTAÇÃO CLIENTE - DNH | B7: ALIMENTAÇÃO
A8: ALIMENTAÇÃO CLIENTE - VISA/MASTERCARD | B8: ALIMENTAÇÃO
A9: ALIMENTAÇÃO FORNECEDOR - VISA/MASTERCARD | B9: ALIMENTAÇÃO
A10: COMBUSTÍVEL - DNH | B10: COMBUSTÍVEL
A11: COMBUSTÍVEL - VISA/MASTERCARD | B11: COMBUSTÍVEL
A12: CONDUÇÃO - DNH | B12: CONDUÇÃO
... A106: COMBUSTÍVEL - DNH | B106: COMBUSTÍVEL

Sheet dimColaborador
A1: COLABORADOR | B1: Cód. Colaborador | C1: SUB-REGIÃO | D1: CANAL | E1: Coluna1
A2: ALLYNE DE OLIVEIRA DYBAS DIAS | B2: 24246 | C2: CONSULTOR DESLIGADO | D2: CONSULTOR DESLIGADO
A3: AMANDA BRANCHER SCALON | B3: 8254 | C3: SUPERVISORA EXTERNA FIRSTLAB | D3: SUPERVISORA EXTERNA FIRSTLAB
A4: AMANDA CAROLINE PORRUA | B4: 25120 | C4: CONSULTOR DESLIGADO | D4: CONSULTOR DESLIGADO
A5: AMANDA FERREIRA MACHADO | B5: 25575 | C5: CONSULTOR DESLIGADO | D5: CONSULTOR DESLIGADO
A6: ANDERSON JUNIOR STOBBE | B6: 999999991 | C6: CONSULTOR DESLIGADO | D6: CONSULTOR DESLIGADO
A7: ANDREIA ANTONIA MACHADO HERNANI FERREIRA | B7: 24052 | C7: CONSULTOR DESLIGADO | D7: CONSULTOR DESLIGADO
A8: ARON DA ROSA FREITAS DE BORBA | B8: 999999992 | C8: CONSULTOR DESLIGADO | D8: CONSULTOR DESLIGADO
A9: ATHAYANE DA CUNHA CARNEIRO | B9: 24057 | C9: CONSULTOR DESLIGADO | D9: CONSULTOR DESLIGADO
A10: BEATRIZ FRANCIELE FERREIRA DOS SANTOS | B10: 23633 | C10: CONSULTOR DESLIGADO | D10: CONSULTOR DESLIGADO
A11: BRUNO MICKAEL BOHR DE OLIVEIRA | B11: 999999993 | C11: TÉCNICO E MANUTENÇÃO | D11: TÉCNICO E MANUTENÇÃO
A12: CAMILA MANFRINATTO | B12: 999999994 | C12: APOIO ADM | D12: APOIO ADM
A13: CAROLINE BRETAS GONCALVES DIAS | B13: 999999995 | C13: QUALIDADE | D13: QUALIDADE
... A38: ALLYNE DIAS | B38: 9999999918 | C38: DR - PRIME - SP | D38: DISTRIBUIDOR
A39: PABLO RODRIGUES DE SOUZA | B39: 9999999919
A40: ALISSON SAMPAIO DE LIMA | B40: 9999999921
A41: VITOR HUGO DE PAIVA SANTOS | B41: 9999999922
A42: PABLO RODRIGUES DE SOUZA | B42: 9999999923
A43: JULIANA FARIA GASPARIN | B43: 9999999924 | E43: Consultora
A44: LUCIANO DA SILVA LOPES | B44: 9999999925
A45: KATIA APARECIDA MARINHO NASCIMENTO | B45: 9999999926
A46: JULIANA FARIA GASPARIN | B46: 9999999927

Sheet dimCentroCusto
A1: Codigo_CentroCusto | B1: Centro_Custo
A2: 014 | B2: INATIVO
A3: 024 | B3: REGIÃO 2
A4: 025 | B4: REGIÃO 3
A5: 026 | B5: REGIÃO 4
A6: 027 | B6: REGIÃO 5
A7: 028 | B7: REGIÃO 6
A8: 029 | B8: COMPRAS
A9: 030 | B9: COMPRAS NACIONAIS
A10: 031 | B10: IMPORTAÇÃO
A11: 032 | B11: SUPRIMENTOS
A12: 033 | B12: MANUTENÇÃO
... A103: -1 | B103: NÃO PREENCHIDO

Sheet dimRepresentantesVendedores
A1: Código | B1: Número CNPJ/CPF | C1: Tipo Pessoa | D1: Nome | E1: Endereço | F1: Bairro | G1: Cidade | H1: Estado | I1: País | J1: Região | K1: Status | L1: Sub-Grupo | M1: Grupo | N1: Tipo | O1: EMAIL | P1: Código Supervisor | Q1: Nome Supervisor
A2: 1460 | B2: 008.331.301-02 | C2: FÍSICO | D2: 1460-RAPHAEL LEME CARNEIRO CESPEDES | E2: RUA ABRÃO CALIXTO | F2: ATUBA | G2: CURITIBA | H2: PR | J2: REGIÃO 01 | K2: ENCERRADO | L2: REGIÃO 01 | M2: CONSULTORES | N2: VENDEDOR
A3: 2230 | B3: 633.712.787-00 | C3: FÍSICO | D3: 2230-EDUARDO EUGÊNIO DE SOUZA MOURA | E3: PRAIA DE BOTAFOGO | F3: BOTAFOGO | G3: RIO DE JANEIRO | H3: RJ | J3: REGIÃO 01 | K3: ENCERRADO | L3: REGIÃO 03 | M3: CONSULTORES | N3: VENDEDOR
A4: 2680 | B4: 055.082.204-61 | C4: FÍSICO | D4: 2680-RODRIGO SANTANA MARTINS DA SILVA | E4: RUA MAITRE CATOLÉ | F4: VÁRZEA | G4: RECIFE | H4: PE | J4: REGIÃO 06 | K4: ENCERRADO | L4: REGIÃO 06 | M4: ASSESSORES | N4: VENDEDOR
A5: 2719 | B5: 006.556.729-31 | C5: FÍSICO | D5: 2719-DANIEL BELIN CAMARGO | E5: RUA MARIA VERÔNICA STROPARO | F5: SÃO BRAZ | G5: CURITIBA | H5: PR | J5: REGIÃO 01 | K5: ENCERRADO | L5: REGIÃO 01 | M5: ASSESSORES | N5: VENDEDOR
A6: 2856 | B6: 082.683.724-78 | C6: FÍSICO | D6: 2856-LAURA BENTO DOS SANTOS | E6: RUA PEDRO CONSTANTINO DA ROCHA | F6: AFONSO PENA | G6: SÃO JOSÉ DOS PINHAIS | H6: PR | J6: REGIÃO 06 | K6: ATIVO | L6: REGIÃO 06 | M6: ASSESSORES | N6: REPRESENTANTE | O6: laura.santos@firstlab.ind.br
A7: 3114 | B7: 080.112.336-45 | C7: FÍSICO | D7: 3114-ALESSANDRA DE CAMPOS MARTINS FONTES | E7: RUA SÍLVIO ANDRADE | F7: SERRANO | G7: BELO HORIZONTE | H7: MG | J7: REGIÃO 01 | K7: ENCERRADO | L7: REGIÃO 05 | M7: CONSULTORES | N7: VENDEDOR
A8: 3285 | B8: 034.884.179-56 | C8: FÍSICO | D8: 3285-ALEXANDRE JACOBUS LOPES | E8: RUA EMILE ZOLA | F8: LINDÓIA | G8: CURITIBA | H8: PR | J8: REGIÃO 01 | K8: ATIVO | L8: REGIÃO 01 | M8: CONSULTORES | N8: VENDEDOR
A9: 3950 | B9: 136.391.978-44 | C9: FÍSICO | D9: 3950-MARCIO UETA | E9: RUA ENGENHEIRO GUILHERME CRISTIANO FRENDER | F9: VILA ANTONIETA | G9: SÃO PAULO | H9: SP | J9: REGIÃO 01 | K9: ENCERRADO | L9: REGIÃO 06 | M9: ASSESSORES | N9: VENDEDOR
A10: 3954 | B10: 016.060.929-10 | C10: FÍSICO | D10: 3954-JACSON DE ALMEIDA POLICANTE | E10: RUA TAMBOARA | F10: CAPÃO DA IMBUIA | G10: CURITIBA | H10: PR | J10: REGIÃO 01 | K10: ENCERRADO | L10: GERAL | M10: CONSULTORES | N10: VENDEDOR
A11: 4268 | B11: 064.409.979-80 | C11: FÍSICO | D11: 4268-GUSTAVO MORETTO BARROS | E11: RUA MARECHAL OTÁVIO SALDANHA MAZZA | F11: CAPÃO RASO | G11: CURITIBA | H11: PR | J11: REGIÃO 01 | K11: ATIVO | L11: REGIÃO 01 | M11: CONSULTORES | N11: VENDEDOR
A12: 4566 | B12: 356.318.788-60 | C12: FÍSICO | D12: 4566-LETICIA DESAN DE GOES | E12: RUA JOSÉ FERREIRA KEFFER | F12: VILA PACÍFICO | G12: BAURU | H12: SP | J12: REGIÃO 01 | K12: ENCERRADO | L12: REGIÃO 02 | M12: CONSULTORES | N12: VENDEDOR
A13: 4567 | B13: 326.022.088-76 | C13: FÍSICO | D13: 4567-RENATA LENITA DA SILVA | E13: AVENIDA VITÓRIO BRIZANTE | F13: JARDIM ZAIRA | G13: MAUÁ | H13: SP | I13: BRASIL | J13: REGIÃO 03 | K13: ATIVO | L13: REGIÃO 03 | M13: CONSULTORES | N13: VENDEDOR
A14: 4608 | B14: 328.562.198-29 | C14: FÍSICO | D14: 4608-JULIANA OLIVI MALTA | E14: AVENIDA PROFESSOR JORGE CORRÊA | F14: CENTRO | G14: ARARAQUARA | H14: SP | J14: REGIÃO 01 | K14: ENCERRADO | L14: REGIÃO 02 | M14: CONSULTORES | N14: VENDEDOR
A15: 5310 | B15: 338.260.768-93 | C15: FÍSICO | D15: 5310-ARISLAINE GOMIERO NOGUEIRA | E15: RUA ANTENOR BORBA | F15: PARQUE LARANJEIRAS | G15: ARARAQUARA | H15: SP | J15: REGIÃO 01 | K15: ENCERRADO | L15: REGIÃO 02 | M15: CONSULTORES | N15: VENDEDOR
A16: 5311 | B16: 016.685.256-23 | C16: FÍSICO | D16: 5311-LEONARDO DE ASSIS ROSA | E16: RUA DEOLINDA CÂNDIDA | F16: BOA VISTA | G16: BELO HORIZONTE | H16: MG | J16: REGIÃO 01 | K16: ENCERRADO | L16: REGIÃO 05 | M16: CONSULTORES | N16: VENDEDOR
A17: 5312 | B17: 032.874.856-01 | C17: FÍSICO | D17: 5312-LUCIANA NOGUEIRA DUARTE | E17: RUA MANILA | F17: ESTRELA DALVA | G17: BELO HORIZONTE | H17: MG | J17: REGIÃO 01 | K17: ENCERRADO | L17: REGIÃO 05 | M17: CONSULTORES | N17: VENDEDOR
A18: 5507 | B18: 089.155.217-06 | C18: FÍSICO | D18: 5507-CHRISTIAN DOS SANTOS CHAGAS | E18: PRAÇA MARTINS LEÃO | F18: ALTO DA BOA VISTA | G18: RIO DE JANEIRO | H18: RJ | J18: REGIÃO 04 | K18: ENCERRADO | L18: REGIÃO 04 | M18: CONSULTORES | N18: VENDEDOR
A19: 5508 | B19: 105.253.097-48 | C19: FÍSICO | D19: 5508-DANIEL ALVES DA CUNHA | E19: AVENIDA SALVADOR ALLENDE | F19: RECREIO DOS BANDEIRANTES | G19: RIO DE JANEIRO | H19: RJ | J19: REGIÃO 04 | K19: ATIVO | L19: REGIÃO 04 | M19: CONSULTORES | N19: VENDEDOR
A20: 7463 | B20: 111.111.111-11 | C20: FÍSICO | D20: 7463-GERAL | G20: CURITIBA | H20: PR | K20: ATIVO | L20: TRIANGULO MINEIRO | M20: CONSULTORES | N20: VENDEDOR | P20: 26101 | Q20: SOEMIA DA SILVA ASSUNCAO
A21: 6789 | B21: 029.999.879-78 | C21: FÍSICO | D21: 6789-RICARDO CAUCA MARZCZAOKOSKI | E21: RUA BERNARDO BUBNIAK | F21: ATUBA | G21: CURITIBA | H21: PR | J21: REGIÃO 01 | K21: INATIVO | L21: REGIÃO 01 | M21: CONSULTORES | N21: VENDEDOR
A22: 6009 | B22: 175.472.548-10 | C22: FÍSICO | D22: 6009-FABIANA MATIOLI | E22: RUA MARACAJÚ | F22: VILA MONTE ALEGRE | G22: RIBEIRÃO PRETO | H22: SP | J22: REGIÃO 02 | K22: ENCERRADO | L22: REGIÃO 02 | M22: CONSULTORES | N22: VENDEDOR
A23: 1061 | B23: 013.374.288-17 | C23: FÍSICO | D23: 1061-ANDRE PAULO ZAJAC | E23: Rua DOUTOR ANTÔNIO MACEDO LIMA | F23: VILA LÚCIA | G23: SÃO PAULO | H23: SP | J23: REGIÃO 03 | K23: ENCERRADO | L23: REGIÃO 03 | M23: CONSULTORES | N23: VENDEDOR
A24: 5771 | B24: 060.036.656-10 | C24: FÍSICO | D24: 5771-LUCIANA CARDOSO DE ANDRADE | E24: RUA DONA CHIQUITA DE CASTRO | F24: BRAÚNAS | G24: BELO HORIZONTE | H24: MG | J24: REGIÃO 05 | K24: ENCERRADO | L24: REGIÃO 05 | M24: CONSULTORES | N24: VENDEDOR
A25: 8074 | B25: 036.339.709-40 | C25: FÍSICO | D25: 8074-ESLEI DE SOUZA XAVIER | E25: RUA CORONEL JOSÉ LEAL FONTOURA | F25: XAXIM | G25: CURITIBA | H25: PR | K25: INATIVO | L25: REGIÃO 01 | M25: CONSULTORES | N25: VENDEDOR
A26: 8148 | B26: 085.722.519-79 | C26: FÍSICO | D26: 8148-CASSIA GABRIELI LOURENÇO | E26: RUA LILIAN VIANA DE ARAÚJO | F26: CIDADE JARDIM | G26: SÃO JOSÉ DOS PINHAIS | H26: PR | J26: REGIÃO 04 | K26: INATIVO | L26: REGIÃO 03 | M26: CONSULTORES | N26: VENDEDOR | O26: cassia.lourenco@firstlab.ind.br | P26: 26101 | Q26: SOEMIA DA SILVA ASSUNCAO
A27: 8218 | B27: 055.928.624-40 | C27: FÍSICO | D27: 8218-LUDHIMILLA GOMES LINS DE LIMA | E27: AVENIDA PINHEIROS | F27: IMBIRIBEIRA | G27: RECIFE | H27: PE | K27: INATIVO | L27: REGIÃO 06 | M27: ASSESSORES | N27: REPRESENTANTE | O27: ludhimilla.lima@firstlab.ind.br
A28: 8254 | B28: 103.939.409-42 | C28: FÍSICO | D28: 8254-AMANDA BRANCHER SCALON | E28: RUA ROSA SAHAGOFF | F28: UBERABA | G28: CURITIBA | H28: PR | J28: REGIÃO 01 | K28: ATIVO | L28: REGIÃO 02 | M28: CONSULTORES | N28: REPRESENTANTE | O28: amanda.scalon@firstlab.ind.br
A29: 8260 | B29: 066.162.129-47 | C29: FÍSICO | D29: 8260-GABRIELLI SCHAFAUSER | E29: RUA OTÁVIO CLAUDINO DE CAMARGO | F29: CRUZEIRO | G29: SÃO JOSÉ DOS PINHAIS | H29: PR | J29: SEM VINCULO C/ REGIÕES | K29: ATIVO | L29: GERAL | M29: CONSULTORES | N29: VENDEDOR | O29: gabrielli.schafauser@firstlab.ind.br | P29: 26101 | Q29: SOEMIA DA SILVA ASSUNCAO
A30: 6242 | B30: 043.070.634-06 | C30: FÍSICO | D30: 6242-GILCLEYA FELIX DE ASSIS | E30: RUA DOUTOR ORLANDO CABRAL | F30: CENTRO | G30: JABOATÃO DOS GUARARAPES | H30: PE | J30: REGIÃO 06 | K30: ENCERRADO | L30: REGIÃO 06 | M30: ASSESSORES | N30: VENDEDOR
A31: 8494 | B31: 660.708.306-44 | C31: FÍSICO | D31: 8494-CHRISTIANO RIZZI TYMBURIBA | E31: RUA DÁLIA - BAIRRO SANTO ANDRE | F31: PEDRO II | G31: BELO HORIZONTE | H31: MG | J31: REGIÃO 05 | K31: INATIVO | L31: REGIÃO 05 | M31: CONSULTORES | N31: VENDEDOR | P31: 151 | Q31: GERAL
A32: 8495 | B32: 044.598.257-83 | C32: FÍSICO | D32: 8495-DANIEL GONÇALVES DE FREITAS | E32: RUA AMOROSO LIMA | F32: CIDADE NOVA | G32: RIO DE JANEIRO | H32: RJ | J32: REGIÃO 04 | K32: INATIVO | L32: REGIÃO 04 | M32: CONSULTORES | N32: VENDEDOR
A33: 8545 | B33: 041.492.339-18 | C33: FÍSICO | D33: 8545-GEOVANA BROTTO RAMOS | E33: RUA PADRE MANUEL DA NÓBREGA | F33: FANNY | G33: CURITIBA | H33: PR | I33: BRASIL | K33: INATIVO | L33: REGIÃO 01 | M33: CONSULTORES | N33: VENDEDOR | P33: 151 | Q33: GERAL
A34: 8571 | B34: 115.870.847-59 | C34: FÍSICO | D34: 8571-TATIANA DI BLASI | E34: RUA DA REPÚBLICA | F34: QUINTINO BOCAIÚVA | G34: RIO DE JANEIRO | H34: RJ | J34: REGIÃO 04 | K34: ENCERRADO | L34: REGIÃO 04 | M34: CONSULTORES | N34: VENDEDOR | O34: tatiana.blasi@kasvi.com.br | P34: 151 | Q34: GERAL
A35: 8572 | B35: 274.267.168-48 | C35: FÍSICO | D35: 8572-BIANCA BRAGATO | E35: RUA ANDRÉA DEL SARTO | F35: TREMEMBÉ | G35: SÃO PAULO | H35: SP | J35: REGIÃO 03 | K35: ENCERRADO | L35: REGIÃO 03 | M35: CONSULTORES | N35: VENDEDOR
A36: 8573 | B36: 039.568.536-28 | C36: FÍSICO | D36: 8573-THIAGO PEREIRA PIRES | E36: RUA JOSE BRAZ DA COSTA VIDAL | F36: CENTRO | G36: VIÇOSA | H36: MG | J36: REGIÃO 05 | K36: ENCERRADO | L36: REGIÃO 05 | M36: CONSULTORES | N36: REPRESENTANTE
A37: 6016 | B37: 319.550.688-28 | C37: FÍSICO | D37: 6016-ANDERSON ANTONIO VILELA SILVEIRA | E37: RUA MARECHAL FLORIANO PEIXOTO | F37: CENTRO | G37: PIRANGI | H37: SP | J37: REGIÃO 02 | K37: INATIVO | L37: REGIÃO 02 | M37: CONSULTORES | N37: VENDEDOR
A38: 8756 | B38: 298.515.208-96 | C38: FÍSICO | D38: 8756-ALESSANDRA FRANCO NEOPICHANOW | E38: RUA CAETANÓPOLIS | F38: JAGUARÉ | G38: SÃO PAULO | H38: SP | K38: ENCERRADO | L38: REGIÃO 02 | M38: CONSULTORES | N38: VENDEDOR | O38: alessandra.franco@firstlab.com.br
A39: 5556 | B39: 064.265.296-13 | C39: FÍSICO | D39: 5556-VITOR ALVES VIGGIANO | E39: RUA DOUTOR JARBAS VIDAL GOMES | F39: CIDADE NOVA | G39: BELO HORIZONTE | H39: MG | J39: REGIÃO 05 | K39: ENCERRADO | L39: REGIÃO 05 | M39: CONSULTORES | N39: VENDEDOR
A40: 8830 | B40: 072.885.546-19 | C40: FÍSICO | D40: 8830-DANIEL FELLIPE FILGUEIRAS ARAUJO | E40: MARTINIANO DE CARVALHO | F40: BELA VISTA | G40: SÃO PAULO | H40: SP | J40: REGIÃO 03 | K40: ENCERRADO | L40: REGIÃO 03 | M40: CONSULTORES | N40: VENDEDOR | O40: daniel.araujo@kasvi.com.br
...

Sheet VW_RelatorioViagensDesoesasCola
A1: DT_DESPESA | B1: NR_VIAGEM | C1: CD_ENTIDADE_FUNC | D1: NM_RAZAOSOC | E1: CD_CENTROCUSTO | F1: DS_CENTROCUSTO | G1: CD_PROJETO | H1: DS_PROJETO | I1: CD_TIPO_DESP_VIAGEM | J1: DS_TIPO_DESP_VIAGEM | K1: nr_despesa | L1: VR_DESPESA | M1: FG_SITUACAO | N1: CLIENTE
A2: 46024 | B2: 2400 | C2: 26136 | D2: JOANA MARIA TEIXEIRA DE OLIVEIRA | E2: 048 | F2: COMERCIAL | G2: 160 | H2: NA - NÃO POSSUI PROJETO | I2: 18 | J2: ALIMENTAÇÃO | K2: 1 | L2: 46.8 | M2: CON | N2: FIRSTLAB INDUSTRIA IMP E EXP DE PROD PARA LABS LTD
A3: 46024 | B3: 2400 | C3: 26136 | D3: JOANA MARIA TEIXEIRA DE OLIVEIRA | E3: 048 | F3: COMERCIAL | G3: 160 | H3: NA - NÃO POSSUI PROJETO | I3: 18 | J3: ALIMENTAÇÃO | K3: 2 | L3: 19.9 | M3: CON | N3: FIRSTLAB INDUSTRIA IMP E EXP DE PROD PARA LABS LTD
A4: 46024 | B4: 2400 | C4: 26136 | D4: JOANA MARIA TEIXEIRA DE OLIVEIRA | E4: 048 | F4: COMERCIAL | G4: 160 | H4: NA - NÃO POSSUI PROJETO | I4: 18 | J4: ALIMENTAÇÃO | K4: 3 | L4: 54.4 | M4: CON | N4: FIRSTLAB INDUSTRIA IMP E EXP DE PROD PARA LABS LTD
A5: 46024 | B5: 2400 | C5: 26136 | D5: JOANA MARIA TEIXEIRA DE OLIVEIRA | E5: 048 | F5: COMERCIAL | G5: 160 | H5: NA - NÃO POSSUI PROJETO | I5: 18 | J5: ALIMENTAÇÃO | K5: 4 | L5: 54.9 | M5: CON | N5: FIRSTLAB INDUSTRIA IMP E EXP DE PROD PARA LABS LTD
A6: 46024 | B6: 2400 | C6: 26136 | D6: JOANA MARIA TEIXEIRA DE OLIVEIRA | E6: 048 | F6: COMERCIAL | G6: 160 | H6: NA - NÃO POSSUI PROJETO | I6: 18 | J6: ALIMENTAÇÃO | K6: 6 | L6: 39.9 | M6: CON | N6: FIRSTLAB INDUSTRIA IMP E EXP DE PROD PARA LABS LTD
A7: 46024 | B7: 2400 | C7: 26136 | D7: JOANA MARIA TEIXEIRA DE OLIVEIRA | E7: 048 | F7: COMERCIAL | G7: 160 | H7: NA - NÃO POSSUI PROJETO | I7: 18 | J7: ALIMENTAÇÃO | K7: 7 | L7: 17 | M7: CON | N7: FIRSTLAB INDUSTRIA IMP E EXP DE PROD PARA LABS LTD
A8: 46024 | B8: 2400 | C8: 26136 | D8: JOANA MARIA TEIXEIRA DE OLIVEIRA | E8: 048 | F8: COMERCIAL | G8: 160 | H8: NA - NÃO POSSUI PROJETO | I8: 18 | J8: ALIMENTAÇÃO | K8: 9 | L8: 75.87 | M8: CON | N8: FIRSTLAB INDUSTRIA IMP E EXP DE PROD PARA LABS LTD
A9: 46024 | B9: 2400 | C9: 26136 | D9: JOANA MARIA TEIXEIRA DE OLIVEIRA | E9: 048 | F9: COMERCIAL | G9: 160 | H9: NA - NÃO POSSUI PROJETO | I9: 18 | J9: ALIMENTAÇÃO | K9: 13 | L9: 41.2 | M9: CON | N9: FIRSTLAB INDUSTRIA IMP E EXP DE PROD PARA LABS LTD
A10: 46024 | B10: 2400 | C10: 26136 | D10: JOANA MARIA TEIXEIRA DE OLIVEIRA | E10: 048 | F10: COMERCIAL | G10: 160 | H10: NA - NÃO POSSUI PROJETO | I10: 18 | J10: ALIMENTAÇÃO | K10: 14 | L10: 85.5 | M10: CON | N10: FIRSTLAB INDUSTRIA IMP E EXP DE PROD PARA LABS LTD
A11: 46024 | B11: 2400 | C11: 26136 | D11: JOANA MARIA TEIXEIRA DE OLIVEIRA | E11: 048 | F11: COMERCIAL | G11: 160 | H11: NA - NÃO POSSUI PROJETO | I11: 18 | J11: ALIMENTAÇÃO | K11: 16 | L11: 74 | M11: CON | N11: FIRSTLAB INDUSTRIA IMP E EXP DE PROD PARA LABS LTD
A12: 46024 | B12: 2400 | C12: 26136 | D12: JOANA MARIA TEIXEIRA DE OLIVEIRA | E12: 048 | F12: COMERCIAL | G12: 160 | H12: NA - NÃO POSSUI PROJETO | I12: 18 | J12: ALIMENTAÇÃO | K12: 17 | L12: 18 | M12: CON | N12: FIRSTLAB INDUSTRIA IMP E EXP DE PROD PARA LABS LTD
A13: 46024 | B13: 2400 | C13: 26136 | D13: JOANA MARIA TEIXEIRA DE OLIVEIRA | E13: 048 | F13: COMERCIAL | G13: 160 | H13: NA - NÃO POSSUI PROJETO | I13: 18 | J13: ALIMENTAÇÃO | K13: 19 | L13: 48.9 | M13: CON | N13: FIRSTLAB INDUSTRIA IMP E EXP DE PROD PARA LABS LTD
... A102: 46052 | B102: 2420 | C102: 25745 | D102: MARCIO ARRUDA LUZ | E102: 048 | F102: COMERCIAL | G102: 160 | H102: NA - NÃO POSSUI PROJETO | I102: 11 | J102: CONDUÇÃO | K102: 11 | L102: 150 | M102: CON | N102: FIRSTLAB INDUSTRIA IMP E EXP DE PROD PARA LABS LTD
A103: 46055 | B103: 2421 | C103: 27576 | D103: JULIANA FARIA GASPARIN | I103: 7 | J103: ALIMENTAÇÃO | K103: 2 | L103: 64.5 | M103: CON | N103: LIMED - MATERIAIS MEDICO HOSPITALAR E LABORATORIAL
A104: 46055 | B104: 2421 | C104: 27576 | D104: JULIANA FARIA GASPARIN | I104: 7 | J104: ALIMENTAÇÃO | K104: 3 | L104: 20.9 | M104: CON | N104: LICIMASTER DIST DE MED E PROD MÉDICO HOSP EIRELLI - EPP
A105: 46055 | B105: 2421 | C105: 27576 | D105: JULIANA FARIA GASPARIN | I105: 7 | J105: ALIMENTAÇÃO | K105: 4 | L105: 60 | M105: CON | N105: CONECT SOLUCOES DIAGNOSTICO LIMITADA
A106: 46055 | B106: 2421 | C106: 27576 | D106: JULIANA FARIA GASPARIN | I106: 7 | J106: ALIMENTAÇÃO | K106: 5 | L106: 70 | M106: CON | N106: CONECT SOLUCOES DIAGNOSTICO LIMITADA
A107: 46055 | B107: 2421 | C107: 27576 | D107: JULIANA FARIA GASPARIN | I107: 7 | J107: ALIMENTAÇÃO | K107: 6 | L107: 29.7 | M107: CON | N107: CONECT SOLUCOES DIAGNOSTICO LIMITADA
A108: 46055 | B108: 2421 | C108: 27576 | D108: JULIANA FARIA GASPARIN | I108: 7 | J108: ALIMENTAÇÃO | K108: 7 | L108: 86.09 | M108: CON | N108: CONECT SOLUCOES DIAGNOSTICO LIMITADA
A109: 46055 | B109: 2421 | C109: 27576 | D109: JULIANA FARIA GASPARIN | I109: 11 | J109: CONDUÇÃO | K109: 8 | L109: 421.1 | M109: CON | N109: CONECT SOLUCOES DIAGNOSTICO LIMITADA
A110: 46055 | B110: 2421 | C110: 27576 | D110: JULIANA FARIA GASPARIN | E110: 048 | F110: COMERCIAL | G110: 160 | H110: NA - NÃO POSSUI PROJETO | I110: 7 | J110: ALIMENTAÇÃO | K110: 1 | L110: 47.7 | M110: CON | N110: CONECT SOLUCOES DIAGNOSTICO LIMITADA
A111: 46055 | B111: 2422 | C111: 27576 | D111: JULIANA FARIA GASPARIN | I111: 7 | J111: ALIMENTAÇÃO | K111: 2 | L111: 60 | M111: CON | N111: LABSHOP LTDA ME
A112: 46055 | B112: 2422 | C112: 27576 | D112: JULIANA FARIA GASPARIN | I112: 7 | J112: ALIMENTAÇÃO | K112: 3 | L112: 45.43 | M112: CON | N112: LABSHOP LTDA ME
A113: 46055 | B113: 2422 | C113: 27576 | D113: JULIANA FARIA GASPARIN | I113: 7 | J113: ALIMENTAÇÃO | K113: 4 | L113: 60.47 | M113: CON | N113: LABSHOP LTDA ME
A114: 46055 | B114: 2422 | C114: 27576 | D114: JULIANA FARIA GASPARIN | I114: 7 | J114: ALIMENTAÇÃO | K114: 5 | L114: 23 | M114: CON | N114: LABSHOP LTDA ME
A115: 46055 | B115: 2422 | C115: 27576 | D115: JULIANA FARIA GASPARIN | I115: 7 | J115: ALIMENTAÇÃO | K115: 6 | L115: 82.8 | M115: CON | N115: LABSHOP LTDA ME
A116: 46055 | B116: 2422 | C116: 27576 | D116: JULIANA FARIA GASPARIN | I116: 7 | J116: ALIMENTAÇÃO | K116: 7 | L116: 48.36 | M116: CON | N116: LABSHOP LTDA ME
A117: 46055 | B117: 2422 | C117: 27576 | D117: JULIANA FARIA GASPARIN | I117: 7 | J117: ALIMENTAÇÃO | K117: 8 | L117: 10.36 | M117: CON | N117: LABSHOP LTDA ME
A118: 46055 | B118: 2422 | C118: 27576 | D118: JULIANA FARIA GASPARIN | I118: 7 | J118: ALIMENTAÇÃO | K118: 9 | L118: 49.63 | M118: CON | N118: LABSHOP LTDA ME
A119: 46055 | B119: 2422 | C119: 27576 | D119: JULIANA FARIA GASPARIN | I119: 10 | J119: ESTACIONAMENTO | K119: 10 | L119: 15.5 | M119: CON | N119: LABSHOP LTDA ME
A120: 46055 | B120: 2422 | C120: 27576 | D120: JULIANA FARIA GASPARIN | I120: 10 | J120: ESTACIONAMENTO | K120: 11 | L120: 8 | M120: CON | N120: LABSHOP LTDA ME
A121: 46055 | B121: 2422 | C121: 27576 | D121: JULIANA FARIA GASPARIN | I121: 25 | J121: COMBUSTÍVEL | K121: 12 | L121: 108.45 | M121: CON | N121: LABSHOP LTDA ME
A122: 46055 | B122: 2422 | C122: 27576 | D122: JULIANA FARIA GASPARIN | I122: 25 | J122: COMBUSTÍVEL | K122: 13 | L122: 92.91 | M122: CON | N122: LABSHOP LTDA ME
A123: 46055 | B123: 2422 | C123: 27576 | D123: JULIANA FARIA GASPARIN | E123: 048 | F123: COMERCIAL | G123: 160 | H123: NA - NÃO POSSUI PROJETO | I123: 7 | J123: ALIMENTAÇÃO | K123: 1 | L123: 21.51 | M123: CON | N123: LABSHOP LTDA ME
A124: 46055 | B124: 2423 | C124: 27576 | D124: JULIANA FARIA GASPARIN | I124: 7 | J124: ALIMENTAÇÃO | K124: 2 | L124: 54 | M124: CON | N124: FIRSTLAB INDUSTRIA IMP E EXP DE PROD PARA LABORATO
A125: 46055 | B125: 2423 | C125: 27576 | D125: JULIANA FARIA GASPARIN | I125: 7 | J125: ALIMENTAÇÃO | K125: 3 | L125: 44.9 | M125: CON | N125: FIRSTLAB INDUSTRIA IMP E EXP DE PROD PARA LABORATO
A126: 46055 | B126: 2423 | C126: 27576 | D126: JULIANA FARIA GASPARIN | I126: 7 | J126: ALIMENTAÇÃO | K126: 4 | L126: 43.32 | M126: CON | N126: FIRSTLAB INDUSTRIA IMP E EXP DE PROD PARA LABORATO
A127: 46055 | B127: 2423 | C127: 27576 | D127: JULIANA FARIA GASPARIN | I127: 7 | J127: ALIMENTAÇÃO | K127: 5 | L127: 240 | M127: CON | N127: FIRSTLAB INDUSTRIA IMP E EXP DE PROD PARA LABORATO
A128: 46055 | B128: 2423 | C128: 27576 | D128: JULIANA FARIA GASPARIN | I128: 7 | J128: ALIMENTAÇÃO | K128: 6 | L128: 33.86 | M128: CON | N128: FIRSTLAB INDUSTRIA IMP E EXP DE PROD PARA LABORATO
...

Sheet Base - AG1
A1: Data Venda | B1: Venda Nº | C1: Nrs. FT (Cli) | D1: Produto | E1: Nome Cia | F1: Conta | G1: Nome Cliente | H1: Desc. C. Custo Cliente | I1: Cód centro de custo | J1: Centro de Custo | K1: Departamento | L1: Motivo Viagem | M1: Solicitante | N1: Colaborador | O1: Colaborador - De Para | P1: Cód. Colaborador | Q1: SUB-REGIÃO | R1: CANAL | S1: Cidade Cia | T1: Rota Resumida | U1: Dt. Início Serviços | V1: Dt. Fim Serviços | W1: Form | X1: Nr. Doc | Y1: Total Tarifa | Z1: Total Taxas | AA1: Total Fee | AB1: Total Cliente
A2: 45838 | B2: 50382 | C2: 6699 | D2: CAR | E2: UNIDAS | F2: =_xlfn.XLOOKUP(E2,DEPARA!A:A,DEPARA!C:C,"Verificar") -> LOCAÇÃO DE VEÍCULOS | G2: FIRSTLAB IND. IMP. E EXP. DE PROD. PARA LAB. LTDA | H2: 055-EQUIPE COMERCIAL 3 | I2: =_xlfn.XLOOKUP(fatoG1[[#This Row],[Centro de Custo]],dimCentroCusto[Centro_Custo],dimCentroCusto[Codigo_CentroCusto]) -> #N/A | J2: =fatoG1[[#This Row],[Desc. C. Custo Cliente]] -> 055-EQUIPE COMERCIAL 3 | L2: VISITA CLIENTES DA REGIÃO | N2: LUZ/MARCIO ARRUDA | O2: =_xlfn.XLOOKUP(N2,DEPARA!F:F,DEPARA!H:H,0) -> MARCIO ARRUDA LUZ | P2: =_xlfn.XLOOKUP(O2,dimColaborador!A:A,dimColaborador!B:B,0) -> 25745 | Q2: =_xlfn.XLOOKUP(O2,dimColaborador!A:A,dimColaborador!C:C,) -> GC - MÉDIO/GRANDE PORTE - SE/CO | R2: =_xlfn.XLOOKUP(O2,dimColaborador!A:A,dimColaborador!D:D) -> GRANDES CONTAS | S2: CURITIBA | T2: 10/06/25 a 12/06/25 - VOLKSWAGEN POLO 200 TSI, PEUGEOT 208, | U2: 45818 | V2: 45820 | W2: 2118 | X2: 508546 | Y2: 364.76 | Z2: 32.9 | AA2: 0 | AB2: 397.66
A3: 45838 | B3: 50383 | C3: 6699 | D3: CAR | E3: UNIDAS | F3: =_xlfn.XLOOKUP(E3,DEPARA!A:A,DEPARA!C:C,"Verificar") -> LOCAÇÃO DE VEÍCULOS | G3: FIRSTLAB IND. IMP. E EXP. DE PROD. PARA LAB. LTDA | H3: 055-EQUIPE COMERCIAL 3 | I3: =_xlfn.XLOOKUP(fatoG1[[#This Row],[Centro de Custo]],dimCentroCusto[Centro_Custo],dimCentroCusto[Codigo_CentroCusto]) -> #N/A | J3: =fatoG1[[#This Row],[Desc. C. Custo Cliente]] -> 055-EQUIPE COMERCIAL 3 | L3: VISITA CLIENTES DA REGIÃO | N3: LUZ/MARCIO ARRUDA | O3: =_xlfn.XLOOKUP(N3,DEPARA!F:F,DEPARA!H:H,0) -> MARCIO ARRUDA LUZ | P3: =_xlfn.XLOOKUP(O3,dimColaborador!A:A,dimColaborador!B:B,0) -> 25745 | Q3: =_xlfn.XLOOKUP(O3,dimColaborador!A:A,dimColaborador!C:C,) -> GC - MÉDIO/GRANDE PORTE - SE/CO | R3: =_xlfn.XLOOKUP(O3,dimColaborador!A:A,dimColaborador!D:D) -> GRANDES CONTAS | S3: CURITIBA | T3: 12/06/25 a 13/06/25 - VOLKSWAGEN POLO 200 TSI, PEUGEOT 208, | U3: 45820 | V3: 45821 | W3: 2118 | X3: 508585 | Y3: 182.38 | Z3: 0 | AA3: 0 | AB3: 182.38
A4: 45832 | B4: 50395 | C4: 6699 | D4: HTL | E4: SCALA RESIDENCE HOTEL | F4: =_xlfn.XLOOKUP(E4,DEPARA!A:A,DEPARA!C:C,"Verificar") -> HOSPEDAGEM | G4: FIRSTLAB IND. IMP. E EXP. DE PROD. PARA LAB. LTDA | H4: 055-EQUIPE COMERCIAL 3 | I4: =_xlfn.XLOOKUP(fatoG1[[#This Row],[Centro de Custo]],dimCentroCusto[Centro_Custo],dimCentroCusto[Codigo_CentroCusto]) -> #N/A | J4: =fatoG1[[#This Row],[Desc. C. Custo Cliente]] -> 055-EQUIPE COMERCIAL 3 | L4: VISITA CLIENTES DA REGIÃO | N4: LUZ/MARCIO ARRUDA | O4: =_xlfn.XLOOKUP(N4,DEPARA!F:F,DEPARA!H:H,0) -> MARCIO ARRUDA LUZ | P4: =_xlfn.XLOOKUP(O4,dimColaborador!A:A,dimColaborador!B:B,0) -> 25745 | Q4: =_xlfn.XLOOKUP(O4,dimColaborador!A:A,dimColaborador!C:C,) -> GC - MÉDIO/GRANDE PORTE - SE/CO | R4: =_xlfn.XLOOKUP(O4,dimColaborador!A:A,dimColaborador!D:D) -> GRANDES CONTAS | S4: RESENDE | T4: 01 SUÍTES - 23/06/25 a 24/06/25 | U4: 45831 | V4: 45832 | W4: 4 | X4: 703598 | Y4: 274.67 | Z4: 0 | AA4: 0 | AB4: 274.67
A5: 45833 | B5: 50421 | C5: 6699 | D5: HTL | E5: FENIX POUSO ALEGRE HOTEL | F5: =_xlfn.XLOOKUP(E5,DEPARA!A:A,DEPARA!C:C,"Verificar") -> HOSPEDAGEM | G5: FIRSTLAB IND. IMP. E EXP. DE PROD. PARA LAB. LTDA | H5: 055-EQUIPE COMERCIAL 3 | I5: =_xlfn.XLOOKUP(fatoG1[[#This Row],[Centro de Custo]],dimCentroCusto[Centro_Custo],dimCentroCusto[Codigo_CentroCusto]) -> #N/A | J5: =fatoG1[[#This Row],[Desc. C. Custo Cliente]] -> 055-EQUIPE COMERCIAL 3 | L5: VISITA CLIENTES DA REGIÃO | N5: LUZ/MARCIO ARRUDA | O5: =_xlfn.XLOOKUP(N5,DEPARA!F:F,DEPARA!H:H,0) -> MARCIO ARRUDA LUZ | P5: =_xlfn.XLOOKUP(O5,dimColaborador!A:A,dimColaborador!B:B,0) -> 25745 | Q5: =_xlfn.XLOOKUP(O5,dimColaborador!A:A,dimColaborador!C:C,) -> GC - MÉDIO/GRANDE PORTE - SE/CO | R5: =_xlfn.XLOOKUP(O5,dimColaborador!A:A,dimColaborador!D:D) -> GRANDES CONTAS | S5: POUSO ALEGRE | T5: 01 QUARTO STANDARD CASAL - 24/06/25 a 25/06/25 | U5: 45832 | V5: 45833 | W5: 4 | X5: 704624 | Y5: 222 | Z5: 11.1 | AA5: 0 | AB5: 233.1
A6: 45834 | B6: 50423 | C6: 6699 | D6: HTL | E6: HOTEL DO PAPAI NOEL | F6: =_xlfn.XLOOKUP(E6,DEPARA!A:A,DEPARA!C:C,"Verificar") -> HOSPEDAGEM | G6: FIRSTLAB IND. IMP. E EXP. DE PROD. PARA LAB. LTDA | H6: 055-EQUIPE COMERCIAL 3 | I6: =_xlfn.XLOOKUP(fatoG1[[#This Row],[Centro de Custo]],dimCentroCusto[Centro_Custo],dimCentroCusto[Codigo_CentroCusto]) -> #N/A | J6: =fatoG1[[#This Row],[Desc. C. Custo Cliente]] -> 055-EQUIPE COMERCIAL 3 | N6: MARCIO ARRUDA LUZ | O6: =_xlfn.XLOOKUP(N6,DEPARA!F:F,DEPARA!H:H,0) -> MARCIO ARRUDA LUZ | P6: =_xlfn.XLOOKUP(O6,dimColaborador!A:A,dimColaborador!B:B,0) -> 25745 | Q6: =_xlfn.XLOOKUP(O6,dimColaborador!A:A,dimColaborador!C:C,) -> GC - MÉDIO/GRANDE PORTE - SE/CO | R6: =_xlfn.XLOOKUP(O6,dimColaborador!A:A,dimColaborador!D:D) -> GRANDES CONTAS | S6: ITATIAI | T6: 01 SUPER LUXO SINGLE - 25/06/25 a 26/06/25 | U6: 45833 | V6: 45834 | W6: 4 | X6: 704625 | Y6: 231.51 | Z6: 0 | AA6: 0 | AB6: 231.51
A7: 45838 | B7: 51762 | C7: 6699 | D7: CAR | E7: UNIDAS | F7: =_xlfn.XLOOKUP(E7,DEPARA!A:A,DEPARA!C:C,"Verificar") -> LOCAÇÃO DE VEÍCULOS | G7: FIRSTLAB IND. IMP. E EXP. DE PROD. PARA LAB. LTDA | H7: 056-EQUIPE COMERCIAL 4 | I7: =_xlfn.XLOOKUP(fatoG1[[#This Row],[Centro de Custo]],dimCentroCusto[Centro_Custo],dimCentroCusto[Codigo_CentroCusto]) -> #N/A | J7: =fatoG1[[#This Row],[Desc. C. Custo Cliente]] -> 056-EQUIPE COMERCIAL 4 | N7: GONCALVES/THIAGO NARCISO OLIVEIRA | O7: =_xlfn.XLOOKUP(N7,DEPARA!F:F,DEPARA!H:H,0) -> THIAGO NARCISO OLIVEIRA GONÇALVES | P7: =_xlfn.XLOOKUP(O7,dimColaborador!A:A,dimColaborador!B:B,0) -> 26516 | Q7: =_xlfn.XLOOKUP(O7,dimColaborador!A:A,dimColaborador!C:C,) -> DR - PRIME - CENTRO OESTE | R7: =_xlfn.XLOOKUP(O7,dimColaborador!A:A,dimColaborador!D:D) -> DISTRIBUIDOR | S7: CURITIBA | T7: 16/06/25 a 18/06/25 - FIAT ARGO, CHEVROLET ONIX, VW GOL (1. | U7: 45824 | V7: 45826 | W7: 2118 | X7: 615605 | Y7: 298 | Z7: 54.9 | AA7: 0 | AB7: 352.9
A8: 45833 | B8: 51764 | C8: 6699 | D8: HTL | E8: IBIS STYLES GOIANIA SHOPPING ESTACAO | F8: =_xlfn.XLOOKUP(E8,DEPARA!A:A,DEPARA!C:C,"Verificar") -> HOSPEDAGEM | G8: FIRSTLAB IND. IMP. E EXP. DE PROD. PARA LAB. LTDA | H8: 056-EQUIPE COMERCIAL 4 | I8: =_xlfn.XLOOKUP(fatoG1[[#This Row],[Centro de Custo]],dimCentroCusto[Centro_Custo],dimCentroCusto[Codigo_CentroCusto]) -> #N/A | J8: =fatoG1[[#This Row],[Desc. C. Custo Cliente]] -> 056-EQUIPE COMERCIAL 4 | N8: GONCALVES/THIAGO NARCISO OLIVEIRA | O8: =_xlfn.XLOOKUP(N8,DEPARA!F:F,DEPARA!H:H,0) -> THIAGO NARCISO OLIVEIRA GONÇALVES | P8: =_xlfn.XLOOKUP(O8,dimColaborador!A:A,dimColaborador!B:B,0) -> 26516 | Q8: =_xlfn.XLOOKUP(O8,dimColaborador!A:A,dimColaborador!C:C,) -> DR - PRIME - CENTRO OESTE | R8: =_xlfn.XLOOKUP(O8,dimColaborador!A:A,dimColaborador!D:D) -> DISTRIBUIDOR | S8: GOIANIA | T8: 01 DBC APARTAMENTO STANDARD COM 1 CAMA CASAL SEM - 23/06/ | U8: 45831 | V8: 45833 | W8: 4000 | X8: 430904 | Y8: 583.85 | Z8: 11.69 | AA8: 0 | AB8: 595.54
A9: 45835 | B9: 51766 | C9: 6699 | D9: HTL | E9: BRISA TOWER BRASILIA HOTEL | F9: =_xlfn.XLOOKUP(E9,DEPARA!A:A,DEPARA!C:C,"Verificar") -> HOSPEDAGEM | G9: FIRSTLAB IND. IMP. E EXP. DE PROD. PARA LAB. LTDA | H9: 056-EQUIPE COMERCIAL 4 | I9: =_xlfn.XLOOKUP(fatoG1[[#This Row],[Centro de Custo]],dimCentroCusto[Centro_Custo],dimCentroCusto[Codigo_CentroCusto]) -> #N/A | J9: =fatoG1[[#This Row],[Desc. C. Custo Cliente]] -> 056-EQUIPE COMERCIAL 4 | N9: GONCALVES/THIAGO NARCISO OLIVEIRA | O9: =_xlfn.XLOOKUP(N9,DEPARA!F:F,DEPARA!H:H,0) -> THIAGO NARCISO OLIVEIRA GONÇALVES | P9: =_xlfn.XLOOKUP(O9,dimColaborador!A:A,dimColaborador!B:B,0) -> 26516 | Q9: =_xlfn.XLOOKUP(O9,dimColaborador!A:A,dimColaborador!C:C,) -> DR - PRIME - CENTRO OESTE | R9: =_xlfn.XLOOKUP(O9,dimColaborador!A:A,dimColaborador!D:D) -> DISTRIBUIDOR | S9: BRASÍLIA | T9: 01 SUÍTE LUXO - 25/06/25 a 27/06/25 | U9: 45833 | V9: 45835 | W9: 2025 | X9: 60317 | Y9: 540 | Z9: 81 | AA9: 0 | AB9: 621
A10: 45838 | B10: 51872 | C10: 6699 | D10: CAR | E10: UNIDAS | F10: =_xlfn.XLOOKUP(E10,DEPARA!A:A,DEPARA!C:C,"Verificar") -> LOCAÇÃO DE VEÍCULOS | G10: FIRSTLAB IND. IMP. E EXP. DE PROD. PARA LAB. LTDA | H10: 056-EQUIPE COMERCIAL 4 | I10: =_xlfn.XLOOKUP(fatoG1[[#This Row],[Centro de Custo]],dimCentroCusto[Centro_Custo],dimCentroCusto[Codigo_CentroCusto]) -> #N/A | J10: =fatoG1[[#This Row],[Desc. C. Custo Cliente]] -> 056-EQUIPE COMERCIAL 4 | N10: ALMEIDA/KHARLA NAYARA ABRANTES | O10: =_xlfn.XLOOKUP(N10,DEPARA!F:F,DEPARA!H:H,0) -> KHARLA NAYARA ABRANTES DE ALMEIDA | P10: =_xlfn.XLOOKUP(O10,dimColaborador!A:A,dimColaborador!B:B,0) -> 26175 | Q10: =_xlfn.XLOOKUP(O10,dimColaborador!A:A,dimColaborador!C:C,) -> GC -MÉDIO/GRANDE PORTE - NO/NE | R10: =_xlfn.XLOOKUP(O10,dimColaborador!A:A,dimColaborador!D:D) -> GRANDES CONTAS | S10: CURITIBA | T10: 09/06/25 a 16/06/25 - VOLKSWAGEN POLO 200 TSI, PEUGEOT 208, | U10: 45817 | V10: 45824 | W10: 2118 | X10: 621530 | Y10: 1074.01 | Z10: 54.9 | AA10: 0 | AB10: 1128.91
A11: 45834 | B11: 52330 | C11: 6699 | D11: HTL | E11: HOTEL NACIONAL DE RIO PRETO | F11: =_xlfn.XLOOKUP(E11,DEPARA!A:A,DEPARA!C:C,"Verificar") -> HOSPEDAGEM | G11: FIRSTLAB IND. IMP. E EXP. DE PROD. PARA LAB. LTDA | H11: 048-COMERCIAL INTERNO | I11: =_xlfn.XLOOKUP(fatoG1[[#This Row],[Centro de Custo]],dimCentroCusto[Centro_Custo],dimCentroCusto[Codigo_CentroCusto]) -> #N/A | J11: =fatoG1[[#This Row],[Desc. C. Custo Cliente]] -> 048-COMERCIAL INTERNO | L11: VISITA COMERCIAL | N11: PEREIRA/FELIPE LUIZ RIBEIRO | O11: =_xlfn.XLOOKUP(N11,DEPARA!F:F,DEPARA!H:H,0) -> FELIPE LUIZ RIBEIRO PEREIRA | P11: =_xlfn.XLOOKUP(O11,dimColaborador!A:A,dimColaborador!B:B,0) -> 26387 | Q11: =_xlfn.XLOOKUP(O11,dimColaborador!A:A,dimColaborador!C:C,) -> GC - MÉDIO/GRANDE PORTE - SP | R11: =_xlfn.XLOOKUP(O11,dimColaborador!A:A,dimColaborador!D:D) -> GRANDES CONTAS | S11: SAO JOSE DO RIO PRETO | T11: 01 STANDARD CASAL 1 CAMA QUEEN - 24/06/25 a 26/06/25 | U11: 45832 | V11: 45834 | W11: 4000 | X11: 470873 | Y11: 610 | Z11: 79.3 | AA11: 0 | AB11: 689.3
A12: 45832 | B12: 52473 | C12: 6699 | D12: TKT | E12: GOL LINHAS AÉREAS | F12: =_xlfn.XLOOKUP(E12,DEPARA!A:A,DEPARA!C:C,"Verificar") -> PASSAGEM | G12: FIRSTLAB IND. IMP. E EXP. DE PROD. PARA LAB. LTDA | H12: 056-EQUIPE COMERCIAL 4 | I12: =_xlfn.XLOOKUP(fatoG1[[#This Row],[Centro de Custo]],dimCentroCusto[Centro_Custo],dimCentroCusto[Codigo_CentroCusto]) -> #N/A | J12: =fatoG1[[#This Row],[Desc. C. Custo Cliente]] -> 056-EQUIPE COMERCIAL 4 | L12: VISITA COMERCIAL | N12: ALMEIDA/KHARLA NAYARA ABRANTES | O12: =_xlfn.XLOOKUP(N12,DEPARA!F:F,DEPARA!H:H,0) -> KHARLA NAYARA ABRANTES DE ALMEIDA | P12: =_xlfn.XLOOKUP(O12,dimColaborador!A:A,dimColaborador!B:B,0) -> 26175 | Q12: =_xlfn.XLOOKUP(O12,dimColaborador!A:A,dimColaborador!C:C,) -> GC -MÉDIO/GRANDE PORTE - NO/NE | R12: =_xlfn.XLOOKUP(O12,dimColaborador!A:A,dimColaborador!D:D) -> GRANDES CONTAS | S12: SAO JOSE DOS PINHAIS | T12: JPA*GIG/CWB | U12: 45930 | V12: 45930 | W12: 2140 | X12: 116838 | Y12: 713.9 | Z12: 51.67 | AA12: 57.11 | AB12: 822.68
A13: 45832 | B13: 52474 | C13: 6699 | D13: TKT | E13: TAM LINHAS AÉREAS | F13: =_xlfn.XLOOKUP(E13,DEPARA!A:A,DEPARA!C:C,"Verificar") -> PASSAGEM | G13: FIRSTLAB IND. IMP. E EXP. DE PROD. PARA LAB. LTDA | H13: 056-EQUIPE COMERCIAL 4 | I13: =_xlfn.XLOOKUP(fatoG1[[#This Row],[Centro de Custo]],dimCentroCusto[Centro_Custo],dimCentroCusto[Codigo_CentroCusto]) -> #N/A | J13: =fatoG1[[#This Row],[Desc. C. Custo Cliente]] -> 056-EQUIPE COMERCIAL 4 | L13: VISITA COMERCIAL | N13: ALMEIDA/KHARLA NAYARA ABRANTES | O13: =_xlfn.XLOOKUP(N13,DEPARA!F:F,DEPARA!H:H,0) -> KHARLA NAYARA ABRANTES DE ALMEIDA | P13: =_xlfn.XLOOKUP(O13,dimColaborador!A:A,dimColaborador!B:B,0) -> 26175 | Q13: =_xlfn.XLOOKUP(O13,dimColaborador!A:A,dimColaborador!C:C,) -> GC -MÉDIO/GRANDE PORTE - NO/NE | R13: =_xlfn.XLOOKUP(O13,dimColaborador!A:A,dimColaborador!D:D) -> GRANDES CONTAS | S13: SAO JOSE DOS PINHAIS | T13: CWB*GRU/JPA | U13: 45934 | V13: 45935 | W13: 2238 | X13: 311683 | Y13: 549.54 | Z13: 46.72 | AA13: 43.96 | AB13: 640.22
A14: 45832 | B14: 52475 | C14: 6699 | D14: TKT | E14: TAM LINHAS AÉREAS | F14: =_xlfn.XLOOKUP(E14,DEPARA!A:A,DEPARA!C:C,"Verificar") -> PASSAGEM | G14: FIRSTLAB IND. IMP. E EXP. DE PROD. PARA LAB. LTDA | H14: 056-EQUIPE COMERCIAL 4 | I14: =_xlfn.XLOOKUP(fatoG1[[#This Row],[Centro de Custo]],dimCentroCusto[Centro_Custo],dimCentroCusto[Codigo_CentroCusto]) -> #N/A | J14: =fatoG1[[#This Row],[Desc. C. Custo Cliente]] -> 056-EQUIPE COMERCIAL 4 | N14: ALMEIDA/KHARLA NAYARA ABRANTES | O14: =_xlfn.XLOOKUP(N14,DEPARA!F:F,DEPARA!H:H,0) -> KHARLA NAYARA ABRANTES DE ALMEIDA | P14: =_xlfn.XLOOKUP(O14,dimColaborador!A:A,dimColaborador!B:B,0) -> 26175 | Q14: =_xlfn.XLOOKUP(O14,dimColaborador!A:A,dimColaborador!C:C,) -> GC -MÉDIO/GRANDE PORTE - NO/NE | R14: =_xlfn.XLOOKUP(O14,dimColaborador!A:A,dimColaborador!D:D) -> GRANDES CONTAS | S14: SAO JOSE DOS PINHAIS | T14: FOR/BEL | U14: 45861 | V14: 45861 | W14: 2238 | X14: 311778 | Y14: 779.07 | Z14: 53.57 | AA14: 62.33 | AB14: 894.97
A15: 45832 | B15: 52476 | C15: 6699 | D15: TKT | E15: AZUL LINHAS AÉREAS BRASILEIRAS | F15: =_xlfn.XLOOKUP(E15,DEPARA!A:A,DEPARA!C:C,"Verificar") -> PASSAGEM | G15: FIRSTLAB IND. IMP. E EXP. DE PROD. PARA LAB. LTDA | H15: 056-EQUIPE COMERCIAL 4 | I15: =_xlfn.XLOOKUP(fatoG1[[#This Row],[Centro de Custo]],dimCentroCusto[Centro_Custo],dimCentroCusto[Codigo_CentroCusto]) -> #N/A | J15: =fatoG1[[#This Row],[Desc. C. Custo Cliente]] -> 056-EQUIPE COMERCIAL 4 | N15: NAYARA ABRANTES DE ALMEIDA/KHARLA | O15: =_xlfn.XLOOKUP(N15,DEPARA!F:F,DEPARA!H:H,0) -> KHARLA NAYARA ABRANTES DE ALMEIDA | P15: =_xlfn.XLOOKUP(O15,dimColaborador!A:A,dimColaborador!B:B,0) -> 26175 | Q15: =_xlfn.XLOOKUP(O15,dimColaborador!A:A,dimColaborador!C:C,) -> GC -MÉDIO/GRANDE PORTE - NO/NE | R15: =_xlfn.XLOOKUP(O15,dimColaborador!A:A,dimColaborador!D:D) -> GRANDES CONTAS | S15: SAO PAULO | T15: BEL/REC | U15: 45863 | V15: 45863 | W15: ETKT | X15: OWRWPN | Y15: 718.17 | Z15: 54.45 | AA15: 57.45 | AB15: 830.07
A16: 45832 | B16: 52480 | C16: 6699 | D16: TKT | E16: TAM LINHAS AÉREAS | F16: =_xlfn.XLOOKUP(E16,DEPARA!A:A,DEPARA!C:C,"Verificar") -> PASSAGEM | G16: FIRSTLAB IND. IMP. E EXP. DE PROD. PARA LAB. LTDA | H16: 049-EQUIPE COMERCIAL 1 | I16: =_xlfn.XLOOKUP(fatoG1[[#This Row],[Centro de Custo]],dimCentroCusto[Centro_Custo],dimCentroCusto[Codigo_CentroCusto]) -> #N/A | J16: =fatoG1[[#This Row],[Desc. C. Custo Cliente]] -> 049-EQUIPE COMERCIAL 1 | N16: OLIVEIRA/JOANA MARIA TEIXEIRA DE | O16: =_xlfn.XLOOKUP(N16,DEPARA!F:F,DEPARA!H:H,0) -> JOANA MARIA TEIXEIRA DE OLIVEIRA | P16: =_xlfn.XLOOKUP(O16,dimColaborador!A:A,dimColaborador!B:B,0) -> 26136 | Q16: =_xlfn.XLOOKUP(O16,dimColaborador!A:A,dimColaborador!C:C,) -> GRANDES CONTAS NACIONAIS | R16: =_xlfn.XLOOKUP(O16,dimColaborador!A:A,dimColaborador!D:D) -> GRANDES CONTAS | S16: SAO JOSE DOS PINHAIS | T16: VCP*BSB/POA*BSB/VCP | U16: 45881 | V16: 45883 | W16: 2238 | X16: 355435 | Y16: 619.2 | Z16: 86.34 | AA16: 49.54 | AB16: 755.08
A17: 45832 | B17: 52481 | C17: 6699 | D17: TKT | E17: AZUL LINHAS AÉREAS BRASILEIRAS | F17: =_xlfn.XLOOKUP(E17,DEPARA!A:A,DEPARA!C:C,"Verificar") -> PASSAGEM | G17: FIRSTLAB IND. IMP. E EXP. DE PROD. PARA LAB. LTDA | H17: 049-EQUIPE COMERCIAL 1 | I17: =_xlfn.XLOOKUP(fatoG1[[#This Row],[Centro de Custo]],dimCentroCusto[Centro_Custo],dimCentroCusto[Codigo_CentroCusto]) -> #N/A | J17: =fatoG1[[#This Row],[Desc. C. Custo Cliente]] -> 049-EQUIPE COMERCIAL 1 | N17: MARIA TEIXEIRA DE OLIVEIRA/JOANA | O17: =_xlfn.XLOOKUP(N17,DEPARA!F:F,DEPARA!H:H,0) -> JOANA MARIA TEIXEIRA DE OLIVEIRA | P17: =_xlfn.XLOOKUP(O17,dimColaborador!A:A,dimColaborador!B:B,0) -> 26136 | Q17: =_xlfn.XLOOKUP(O17,dimColaborador!A:A,dimColaborador!C:C,) -> GRANDES CONTAS NACIONAIS | R17: =_xlfn.XLOOKUP(O17,dimColaborador!A:A,dimColaborador!D:D) -> GRANDES CONTAS | S17: SAO PAULO | T17: VCP/FLN/VCP | U17: 45894 | V17: 45897 | W17: ETKT | X17: YIRY4P | Y17: 613.9 | Z17: 81.24 | AA17: 49.11 | AB17: 744.25
A18: 45834 | B18: 52566 | C18: 6699 | D18: TKT | E18: TAM LINHAS AÉREAS | F18: =_xlfn.XLOOKUP(E18,DEPARA!A:A,DEPARA!C:C,"Verificar") -> PASSAGEM | G18: FIRSTLAB IND. IMP. E EXP. DE PROD. PARA LAB. LTDA | H18: 049-EQUIPE COMERCIAL 1 | I18: =_xlfn.XLOOKUP(fatoG1[[#This Row],[Centro de Custo]],dimCentroCusto[Centro_Custo],dimCentroCusto[Codigo_CentroCusto]) -> #N/A | J18: =fatoG1[[#This Row],[Desc. C. Custo Cliente]] -> 049-EQUIPE COMERCIAL 1 | N18: VAZ/LETICIA CAMPOS DA SILVA | O18: =_xlfn.XLOOKUP(N18,DEPARA!F:F,DEPARA!H:H,0) -> LETICIA CAMPOS DA SILVA VAZ | P18: =_xlfn.XLOOKUP(O18,dimColaborador!A:A,dimColaborador!B:B,0) -> 26385 | Q18: =_xlfn.XLOOKUP(O18,dimColaborador!A:A,dimColaborador!C:C,) -> GC - MÉDIO/GRANDE PORTE - SUL | R18: =_xlfn.XLOOKUP(O18,dimColaborador!A:A,dimColaborador!D:D) -> GRANDES CONTAS | S18: SAO JOSE DOS PINHAIS | T18: CWB/IGU/CWB | U18: 45901 | V18: 45904 | W18: 2238 | X18: 642120 | Y18: 567.42 | Z18: 93.74 | AA18: 45.39 | AB18: 706.55
A19: 45834 | B19: 52567 | C19: 6699 | D19: TKT | E19: AZUL LINHAS AÉREAS BRASILEIRAS | F19: =_xlfn.XLOOKUP(E19,DEPARA!A:A,DEPARA!C:C,"Verificar") -> PASSAGEM | G19: FIRSTLAB IND. IMP. E EXP. DE PROD. PARA LAB. LTDA | H19: 049-EQUIPE COMERCIAL 1 | I19: =_xlfn.XLOOKUP(fatoG1[[#This Row],[Centro de Custo]],dimCentroCusto[Centro_Custo],dimCentroCusto[Codigo_CentroCusto]) -> #N/A | J19: =fatoG1[[#This Row],[Desc. C. Custo Cliente]] -> 049-EQUIPE COMERCIAL 1 | N19: VAZ/LETICIA | O19: =_xlfn.XLOOKUP(N19,DEPARA!F:F,DEPARA!H:H,0) -> LETICIA CAMPOS DA SILVA VAZ | P19: =_xlfn.XLOOKUP(O19,dimColaborador!A:A,dimColaborador!B:B,0) -> 26385 | Q19: =_xlfn.XLOOKUP(O19,dimColaborador!A:A,dimColaborador!C:C,) -> GC - MÉDIO/GRANDE PORTE - SUL | R19: =_xlfn.XLOOKUP(O19,dimColaborador!A:A,dimColaborador!D:D) -> GRANDES CONTAS | S19: SAO PAULO | T19: CWB/POA/CWB | U19: 45881 | V19: 45883 | W19: ETKT | X19: LQDHQH | Y19: 546 | Z19: 102.74 | AA19: 43.68 | AB19: 692.42
A20: 45834 | B20: 52571 | C20: 6699 | D20: TKT | E20: TAM LINHAS AÉREAS | F20: =_xlfn.XLOOKUP(E20,DEPARA!A:A,DEPARA!C:C,"Verificar") -> PASSAGEM | G20: FIRSTLAB IND. IMP. E EXP. DE PROD. PARA LAB. LTDA | H20: 056-EQUIPE COMERCIAL 4 | I20: =_xlfn.XLOOKUP(fatoG1[[#This Row],[Centro de Custo]],dimCentroCusto[Centro_Custo],dimCentroCusto[Codigo_CentroCusto]) -> #N/A | J20: =fatoG1[[#This Row],[Desc. C. Custo Cliente]] -> 056-EQUIPE COMERCIAL 4 | N20: GONCALVES/THIAGO NARCISO OLIVEIRA | O20: =_xlfn.XLOOKUP(N20,DEPARA!F:F,DEPARA!H:H,0) -> THIAGO NARCISO OLIVEIRA GONÇALVES | P20: =_xlfn.XLOOKUP(O20,dimColaborador!A:A,dimColaborador!B:B,0) -> 26516 | Q20: =_xlfn.XLOOKUP(O20,dimColaborador!A:A,dimColaborador!C:C,) -> DR - PRIME - CENTRO OESTE | R20: =_xlfn.XLOOKUP(O20,dimColaborador!A:A,dimColaborador!D:D) -> DISTRIBUIDOR | S20: SAO JOSE DOS PINHAIS | T20: BEL*BSB/THE | U20: 45856 | V20: 45856 | W20: 2238 | X20: 682440 | Y20: 926.99 | Z20: 54.45 | AA20: 74.16 | AB20: 1055.6
A21: 45834 | B21: 52572 | C21: 6699 | D21: TKT | E21: TAM LINHAS AÉREAS | F21: =_xlfn.XLOOKUP(E21,DEPARA!A:A,DEPARA!C:C,"Verificar") -> PASSAGEM | G21: FIRSTLAB IND. IMP. E EXP. DE PROD. PARA LAB. LTDA | H21: 056-EQUIPE COMERCIAL 4 | I21: =_xlfn.XLOOKUP(fatoG1[[#This Row],[Centro de Custo]],dimCentroCusto[Centro_Custo],dimCentroCusto[Codigo_CentroCusto]) -> #N/A | J21: =fatoG1[[#This Row],[Desc. C. Custo Cliente]] -> 056-EQUIPE COMERCIAL 4 | N21: GONCALVES/THIAGO NARCISO OLIVEIRA | O21: =_xlfn.XLOOKUP(N21,DEPARA!F:F,DEPARA!H:H,0) -> THIAGO NARCISO OLIVEIRA GONÇALVES | P21: =_xlfn.XLOOKUP(O21,dimColaborador!A:A,dimColaborador!B:B,0) -> 26516 | Q21: =_xlfn.XLOOKUP(O21,dimColaborador!A:A,dimColaborador!C:C,) -> DR - PRIME - CENTRO OESTE | R21: =_xlfn.XLOOKUP(O21,dimColaborador!A:A,dimColaborador!D:D) -> DISTRIBUIDOR | S21: SAO JOSE DOS PINHAIS | T21: THE*FOR/SSA*BSB/THE | U21: 45859 | V21: 45862 | W21: 2238 | X21: 682552 | Y21: 1937.15 | Z21: 91.71 | AA21: 154.97 | AB21: 2183.83
A22: 45834 | B22: 52573 | C22: 6699 | D22: TKT | E22: AZUL LINHAS AÉREAS BRASILEIRAS | F22: =_xlfn.XLOOKUP(E22,DEPARA!A:A,DEPARA!C:C,"Verificar") -> PASSAGEM | G22: FIRSTLAB IND. IMP. E EXP. DE PROD. PARA LAB. LTDA | H22: 056-EQUIPE COMERCIAL 4 | I22: =_xlfn.XLOOKUP(fatoG1[[#This Row],[Centro de Custo]],dimCentroCusto[Centro_Custo],dimCentroCusto[Codigo_CentroCusto]) -> #N/A | J22: =fatoG1[[#This Row],[Desc. C. Custo Cliente]] -> 056-EQUIPE COMERCIAL 4 | N22: NARCISO OLIVEIRA GONCALVES/THIAGO | O22: =_xlfn.XLOOKUP(N22,DEPARA!F:F,DEPARA!H:H,0) -> THIAGO NARCISO OLIVEIRA GONÇALVES | P22: =_xlfn.XLOOKUP(O22,dimColaborador!A:A,dimColaborador!B:B,0) -> 26516 | Q22: =_xlfn.XLOOKUP(O22,dimColaborador!A:A,dimColaborador!C:C,) -> DR - PRIME - CENTRO OESTE | R22: =_xlfn.XLOOKUP(O22,dimColaborador!A:A,dimColaborador!D:D) -> DISTRIBUIDOR | S22: SAO PAULO | T22: MAO/BEL | U22: 45854 | V22: 45854 | W22: ETKT | X22: VDM3HR | Y22: 713.18 | Z22: 51.07 | AA22: 57.05 | AB22: 821.3
A23: 45834 | B23: 52574 | C23: 6699 | D23: TKT | E23: GOL LINHAS AÉREAS | F23: =_xlfn.XLOOKUP(E23,DEPARA!A:A,DEPARA!C:C,"Verificar") -> PASSAGEM | G23: FIRSTLAB IND. IMP. E EXP. DE PROD. PARA LAB. LTDA | H23: 056-EQUIPE COMERCIAL 4 | I23: =_xlfn.XLOOKUP(fatoG1[[#This Row],[Centro de Custo]],dimCentroCusto[Centro_Custo],dimCentroCusto[Codigo_CentroCusto]) -> #N/A | J23: =fatoG1[[#This Row],[Desc. C. Custo Cliente]] -> 056-EQUIPE COMERCIAL 4 | N23: GONCALVES/THIAGO NARCISO OLIVEIRA | O23: =_xlfn.XLOOKUP(N23,DEPARA!F:F,DEPARA!H:H,0) -> THIAGO NARCISO OLIVEIRA GONÇALVES | P23: =_xlfn.XLOOKUP(O23,dimColaborador!A:A,dimColaborador!B:B,0) -> 26516 | Q23: =_xlfn.XLOOKUP(O23,dimColaborador!A:A,dimColaborador!C:C,) -> DR - PRIME - CENTRO OESTE | R23: =_xlfn.XLOOKUP(O23,dimColaborador!A:A,dimColaborador!D:D) -> DISTRIBUIDOR | S23: SAO JOSE DOS PINHAIS | T23: THE*BSB/MAO | U23: 45852 | V23: 45852 | W23: 2140 | X23: 273116 | Y23: 1352.79 | Z23: 47.44 | AA23: 108.22 | AB23: 1508.45
A24: 45838 | B24: 52681 | C24: 6699 | D24: CAR | E24: MOVIDA RENT A CAR | F24: =_xlfn.XLOOKUP(E24,DEPARA!A:A,DEPARA!C:C,"Verificar") -> LOCAÇÃO DE VEÍCULOS | G24: FIRSTLAB IND. IMP. E EXP. DE PROD. PARA LAB. LTDA | H24: 049-EQUIPE COMERCIAL 1 | I24: =_xlfn.XLOOKUP(fatoG1[[#This Row],[Centro de Custo]],dimCentroCusto[Centro_Custo],dimCentroCusto[Codigo_CentroCusto]) -> #N/A | J24: =fatoG1[[#This Row],[Desc. C. Custo Cliente]] -> 049-EQUIPE COMERCIAL 1 | N24: LETICIA CAMPOS DA SILVA VAZ | O24: =_xlfn.XLOOKUP(N24,DEPARA!F:F,DEPARA!H:H,0) -> LETICIA CAMPOS DA SILVA VAZ | P24: =_xlfn.XLOOKUP(O24,dimColaborador!A:A,dimColaborador!B:B,0) -> 26385 | Q24: =_xlfn.XLOOKUP(O24,dimColaborador!A:A,dimColaborador!C:C,) -> GC - MÉDIO/GRANDE PORTE - SUL | R24: =_xlfn.XLOOKUP(O24,dimColaborador!A:A,dimColaborador!D:D) -> GRANDES CONTAS | S24: CURITIBA | T24: 09/12/24 a 13/12/24 - D - AEROP. INTER. PORTO ALEGRE - SALGA | U24: 45635 | V24: 45639 | X24: 0 | Y24: 0 | Z24: 58.4 | AA24: 0 | AB24: 58.4
A25: 45846 | B25: 51359 | C25: 6729 | D25: HTL | E25: NORTH HOTEL | F25: =_xlfn.XLOOKUP(E25,DEPARA!A:A,DEPARA!C:C,"Verificar") -> HOSPEDAGEM | G25: FIRSTLAB IND. IMP. E EXP. DE PROD. PARA LAB. LTDA | H25: 049-EQUIPE COMERCIAL 1 | I25: =_xlfn.XLOOKUP(fatoG1[[#This Row],[Centro de Custo]],dimCentroCusto[Centro_Custo],dimCentroCusto[Codigo_CentroCusto]) -> #N/A | J25: =fatoG1[[#This Row],[Desc. C. Custo Cliente]] -> 049-EQUIPE COMERCIAL 1 | N25: VAZ/LETICIA CAMPOS DA SILVA | O25: =_xlfn.XLOOKUP(N25,DEPARA!F:F,DEPARA!H:H,0) -> LETICIA CAMPOS DA SILVA VAZ | P25: =_xlfn.XLOOKUP(O25,dimColaborador!A:A,dimColaborador!B:B,0) -> 26385 | Q25: =_xlfn.XLOOKUP(O25,dimColaborador!A:A,dimColaborador!C:C,) -> GC - MÉDIO/GRANDE PORTE - SUL | R25: =_xlfn.XLOOKUP(O25,dimColaborador!A:A,dimColaborador!D:D) -> GRANDES CONTAS | S25: CHAPECÓ | T25: 01 SUITE EXECUTIVA LUXO - 07/07/25 a 08/07/25 | U25: 45845 | V25: 45846 | W25: 4 | X25: 771960 | Y25: 265.33 | Z25: 10.61 | AA25: 0 | AB25: 275.94
A26: 45841 | B26: 52413 | C26: 6729 | D26: HTL | E26: OMNIBEES | F26: =_xlfn.XLOOKUP(E26,DEPARA!A:A,DEPARA!C:C,"Verificar") -> HOSPEDAGEM | G26: FIRSTLAB IND. IMP. E EXP. DE PROD. PARA LAB. LTDA | H26: 055-EQUIPE COMERCIAL 3 | I26: =_xlfn.XLOOKUP(fatoG1[[#This Row],[Centro de Custo]],dimCentroCusto[Centro_Custo],dimCentroCusto[Codigo_CentroCusto]) -> #N/A | J26: =fatoG1[[#This Row],[Desc. C. Custo Cliente]] -> 055-EQUIPE COMERCIAL 3 | L26: VISITA CLIENTES DA REGIÃO | N26: LUZ/MARCIO ARRUDA | O26: =_xlfn.XLOOKUP(N26,DEPARA!F:F,DEPARA!H:H,0) -> MARCIO ARRUDA LUZ | P26: =_xlfn.XLOOKUP(O26,dimColaborador!A:A,dimColaborador!B:B,0) -> 25745 | Q26: =_xlfn.XLOOKUP(O26,dimColaborador!A:A,dimColaborador!C:C,) -> GC - MÉDIO/GRANDE PORTE - SE/CO | R26: =_xlfn.XLOOKUP(O26,dimColaborador!A:A,dimColaborador!D:D) -> GRANDES CONTAS | S26: SAO PAULO | T26: 01 APARTAMENTO VISTA PISCINA - 02/07/25 a 03/07/25 | U26: 45840 | V26: 45841 | W26: RES0 | X26: 00161- | Y26: 182.4 | Z26: 8 | AA26: 0 | AB26: 190.4
A27: 45842 | B27: 52414 | C27: 6729 | D27: HTL | E27: TRANSAMERICA FIT VITÓRIA RETA DA PENHA | F27: =_xlfn.XLOOKUP(E27,DEPARA!A:A,DEPARA!C:C,"Verificar") -> HOSPEDAGEM | G27: FIRSTLAB IND. IMP. E EXP. DE PROD. PARA LAB. LTDA | H27: 055-EQUIPE COMERCIAL 3 | I27: =_xlfn.XLOOKUP(fatoG1[[#This Row],[Centro de Custo]],dimCentroCusto[Centro_Custo],dimCentroCusto[Codigo_CentroCusto]) -> #N/A | J27: =fatoG1[[#This Row],[Desc. C. Custo Cliente]] -> 055-EQUIPE COMERCIAL 3 | L27: VISITA CLIENTES DA REGIÃO | N27: LUZ/MARCIO ARRUDA | O27: =_xlfn.XLOOKUP(N27,DEPARA!F:F,DEPARA!H:H,0) -> MARCIO ARRUDA LUZ | P27: =_xlfn.XLOOKUP(O27,dimColaborador!A:A,dimColaborador!B:B,0) -> 25745 | Q27: =_xlfn.XLOOKUP(O27,dimColaborador!A:A,dimColaborador!C:C,) -> GC - MÉDIO/GRANDE PORTE - SE/CO | R27: =_xlfn.XLOOKUP(O27,dimColaborador!A:A,dimColaborador!D:D) -> GRANDES CONTAS | S27: VITORIA | T27: 01 STANDARD QUEEN NÃO FUMANTE - 03/07/25 a 04/07/25 | U27: 45841 | V27: 45842 | W27: 4000 | X27: 474661 | Y27: 303.45 | Z27: 15.17 | AA27: 0 | AB27: 318.62
A28: 45839 | B28: 52534 | C28: 6729 | D28: HTL | E28: HOTEL SANTA CRUZ | F28: =_xlfn.XLOOKUP(E28,DEPARA!A:A,DEPARA!C:C,"Verificar") -> HOSPEDAGEM | G28: FIRSTLAB IND. IMP. E EXP. DE PROD. PARA LAB. LTDA | H28: 049-EQUIPE COMERCIAL 1 | I28: =_xlfn.XLOOKUP(fatoG1[[#This Row],[Centro de Custo]],dimCentroCusto[Centro_Custo],dimCentroCusto[Codigo_CentroCusto]) -> #N/A | J28: =fatoG1[[#This Row],[Desc. C. Custo Cliente]] -> 049-EQUIPE COMERCIAL 1 | N28: VAZ/LETICIA CAMPOS DA SILVA | O28: =_xlfn.XLOOKUP(N28,DEPARA!F:F,DEPARA!H:H,0) -> LETICIA CAMPOS DA SILVA VAZ | P28: =_xlfn.XLOOKUP(O28,dimColaborador!A:A,dimColaborador!B:B,0) -> 26385 | Q28: =_xlfn.XLOOKUP(O28,dimColaborador!A:A,dimColaborador!C:C,) -> GC - MÉDIO/GRANDE PORTE - SUL | R28: =_xlfn.XLOOKUP(O28,dimColaborador!A:A,dimColaborador!D:D) -> GRANDES CONTAS | S28: SANTA CRUZ DO SUL | T28: 01 SUPERIOR - 30/06/25 a 01/07/25 | U28: 45838 | V28: 45839 | W28: 4 | X28: 845934 | Y28: 312.19 | Z28: 0 | AA28: 0 | AB28: 312.19
A29: 45840 | B29: 52535 | C29: 6729 | D29: HTL | E29: TRI HOTEL SMART CAXIAS | F29: =_xlfn.XLOOKUP(E29,DEPARA!A:A,DEPARA!C:C,"Verificar") -> HOSPEDAGEM | G29: FIRSTLAB IND. IMP. E EXP. DE PROD. PARA LAB. LTDA | H29: 049-EQUIPE COMERCIAL 1 | I29: =_xlfn.XLOOKUP(fatoG1[[#This Row],[Centro de Custo]],dimCentroCusto[Centro_Custo],dimCentroCusto[Codigo_CentroCusto]) -> #N/A | J29: =fatoG1[[#This Row],[Desc. C. Custo Cliente]] -> 049-EQUIPE COMERCIAL 1 | N29: VAZ/LETICIA CAMPOS DA SILVA | O29: =_xlfn.XLOOKUP(N29,DEPARA!F:F,DEPARA!H:H,0) -> LETICIA CAMPOS DA SILVA VAZ | P29: =_xlfn.XLOOKUP(O29,dimColaborador!A:A,dimColaborador!B:B,0) -> 26385 | Q29: =_xlfn.XLOOKUP(O29,dimColaborador!A:A,dimColaborador!C:C,) -> GC - MÉDIO/GRANDE PORTE - SUL | R29: =_xlfn.XLOOKUP(O29,dimColaborador!A:A,dimColaborador!D:D) -> GRANDES CONTAS | S29: CAXIAS DO SUL | T29: 01 INDIVIDUAL LUXO - 01/07/25 a 02/07/25 | U29: 45839 | V29: 45840 | W29: 4000 | X29: 480881 | Y29: 229 | Z29: 0 | AA29: 0 | AB29: 229
A30: 45841 | B30: 52536 | C30: 6729 | D30: HTL | E30: IBIS STYLES PORTO ALEGRE CENTRO | F30: =_xlfn.XLOOKUP(E30,DEPARA!A:A,DEPARA!C:C,"Verificar") -> HOSPEDAGEM | G30: FIRSTLAB IND. IMP. E EXP. DE PROD. PARA LAB. LTDA | H30: 049-EQUIPE COMERCIAL 1 | I30: =_xlfn.XLOOKUP(fatoG1[[#This Row],[Centro de Custo]],dimCentroCusto[Centro_Custo],dimCentroCusto[Codigo_CentroCusto]) -> #N/A | J30: =fatoG1[[#This Row],[Desc. C. Custo Cliente]] -> 049-EQUIPE COMERCIAL 1 | N30: VAZ/LETICIA CAMPOS DA SILVA | O30: =_xlfn.XLOOKUP(N30,DEPARA!F:F,DEPARA!H:H,0) -> LETICIA CAMPOS DA SILVA VAZ | P30: =_xlfn.XLOOKUP(O30,dimColaborador!A:A,dimColaborador!B:B,0) -> 26385 | Q30: =_xlfn.XLOOKUP(O30,dimColaborador!A:A,dimColaborador!C:C,) -> GC - MÉDIO/GRANDE PORTE - SUL | R30: =_xlfn.XLOOKUP(O30,dimColaborador!A:A,dimColaborador!D:D) -> GRANDES CONTAS | S30: PORTO ALEGRE | T30: 01 QUARTO STANDARD COM 1 CAMA DE CASAL - 02/07/25 a 03/07/2 | U30: 45840 | V30: 45841 | W30: 4 | X30: 845944 | Y30: 309 | Z30: 15.45 | AA30: 0 | AB30: 324.45
A31: 45839 | B31: 52715 | C31: 6729 | D31: TKT | E31: GOL LINHAS AÉREAS | F31: =_xlfn.XLOOKUP(E31,DEPARA!A:A,DEPARA!C:C,"Verificar") -> PASSAGEM | G31: FIRSTLAB IND. IMP. E EXP. DE PROD. PARA LAB. LTDA | H31: 056-EQUIPE COMERCIAL 4 | I31: =_xlfn.XLOOKUP(fatoG1[[#This Row],[Centro de Custo]],dimCentroCusto[Centro_Custo],dimCentroCusto[Codigo_CentroCusto]) -> #N/A | J31: =fatoG1[[#This Row],[Desc. C. Custo Cliente]] -> 056-EQUIPE COMERCIAL 4 | L31: VISITA A CLIENTE | N31: NARCISO OLIVEIRA GONCALVES/THIAGO | O31: =_xlfn.XLOOKUP(N31,DEPARA!F:F,DEPARA!H:H,0) -> THIAGO NARCISO OLIVEIRA GONÇALVES | P31: =_xlfn.XLOOKUP(O31,dimColaborador!A:A,dimColaborador!B:B,0) -> 26516 | Q31: =_xlfn.XLOOKUP(O31,dimColaborador!A:A,dimColaborador!C:C,) -> DR - PRIME - CENTRO OESTE | R31: =_xlfn.XLOOKUP(O31,dimColaborador!A:A,dimColaborador!D:D) -> DISTRIBUIDOR | S31: SAO JOSE DOS PINHAIS | T31: THE*BSB/REC*SSA*BSB/THE | U31: 45846 | V31: 45850 | W31: 2140 | X31: 542776 | Y31: 3288.38 | Z31: 106.33 | AA31: 263.07 | AB31: 3657.78
A32: 45839 | B32: 52716 | C32: 6729 | D32: TKT | E32: TAM LINHAS AÉREAS | F32: =_xlfn.XLOOKUP(E32,DEPARA!A:A,DEPARA!C:C,"Verificar") -> PASSAGEM | G32: FIRSTLAB IND. IMP. E EXP. DE PROD. PARA LAB. LTDA | H32: 055-EQUIPE COMERCIAL 3 | I32: =_xlfn.XLOOKUP(fatoG1[[#This Row],[Centro de Custo]],dimCentroCusto[Centro_Custo],dimCentroCusto[Codigo_CentroCusto]) -> #N/A | J32: =fatoG1[[#This Row],[Desc. C. Custo Cliente]] -> 055-EQUIPE COMERCIAL 3 | L32: VISITA CLIENTES DA REGIÃO/ TREINAMENTO | N32: LUZ/MARCIO ARRUDA | O32: =_xlfn.XLOOKUP(N32,DEPARA!F:F,DEPARA!H:H,0) -> MARCIO ARRUDA LUZ | P32: =_xlfn.XLOOKUP(O32,dimColaborador!A:A,dimColaborador!B:B,0) -> 25745 | Q32: =_xlfn.XLOOKUP(O32,dimColaborador!A:A,dimColaborador!C:C,) -> GC - MÉDIO/GRANDE PORTE - SE/CO | R32: =_xlfn.XLOOKUP(O32,dimColaborador!A:A,dimColaborador!D:D) -> GRANDES CONTAS | S32: SAO JOSE DOS PINHAIS | T32: GIG*GRU/UDI | U32: 45868 | V32: 45868 | W32: 2239 | X32: 319469 | Y32: 401.58 | Z32: 34.11 | AA32: 32.13 | AB32: 467.82
A33: 45839 | B33: 52717 | C33: 6729 | D33: TKT | E33: GOL LINHAS AÉREAS | F33: =_xlfn.XLOOKUP(E33,DEPARA!A:A,DEPARA!C:C,"Verificar") -> PASSAGEM | G33: FIRSTLAB IND. IMP. E EXP. DE PROD. PARA LAB. LTDA | H33: 055-EQUIPE COMERCIAL 3 | I33: =_xlfn.XLOOKUP(fatoG1[[#This Row],[Centro de Custo]],dimCentroCusto[Centro_Custo],dimCentroCusto[Codigo_CentroCusto]) -> #N/A | J33: =fatoG1[[#This Row],[Desc. C. Custo Cliente]] -> 055-EQUIPE COMERCIAL 3 | L33: VISITA CLIENTES DA REGIÃO/ TREINAMENTO | N33: LUZ/MARCIO ARRUDA | O33: =_xlfn.XLOOKUP(N33,DEPARA!F:F,DEPARA!H:H,0) -> MARCIO ARRUDA LUZ | P33: =_xlfn.XLOOKUP(O33,dimColaborador!A:A,dimColaborador!B:B,0) -> 25745 | Q33: =_xlfn.XLOOKUP(O33,dimColaborador!A:A,dimColaborador!C:C,) -> GC - MÉDIO/GRANDE PORTE - SE/CO | R33: =_xlfn.XLOOKUP(O33,dimColaborador!A:A,dimColaborador!D:D) -> GRANDES CONTAS | S33: SAO JOSE DOS PINHAIS | T33: UDI*CGH/SDU | U33: 45870 | V33: 45870 | W33: 2140 | X33: 543838 | Y33: 445.9 | Z33: 40.96 | AA33: 35.67 | AB33: 522.53
A34: 45839 | B34: 52718 | C34: 6729 | D34: TKT | E34: TAM LINHAS AÉREAS | F34: =_xlfn.XLOOKUP(E34,DEPARA!A:A,DEPARA!C:C,"Verificar") -> PASSAGEM | G34: FIRSTLAB IND. IMP. E EXP. DE PROD. PARA LAB. LTDA | H34: 055-EQUIPE COMERCIAL 3 | I34: =_xlfn.XLOOKUP(fatoG1[[#This Row],[Centro de Custo]],dimCentroCusto[Centro_Custo],dimCentroCusto[Codigo_CentroCusto]) -> #N/A | J34: =fatoG1[[#This Row],[Desc. C. Custo Cliente]] -> 055-EQUIPE COMERCIAL 3 | L34: VISITA CLIENTES DA REGIÃO | N34: LUZ/MARCIO ARRUDA | O34: =_xlfn.XLOOKUP(N34,DEPARA!F:F,DEPARA!H:H,0) -> MARCIO ARRUDA LUZ | P34: =_xlfn.XLOOKUP(O34,dimColaborador!A:A,dimColaborador!B:B,0) -> 25745 | Q34: =_xlfn.XLOOKUP(O34,dimColaborador!A:A,dimColaborador!C:C,) -> GC - MÉDIO/GRANDE PORTE - SE/CO | R34: =_xlfn.XLOOKUP(O34,dimColaborador!A:A,dimColaborador!D:D) -> GRANDES CONTAS | S34: SAO JOSE DOS PINHAIS | T34: SDU*BSB/GYN | U34: 45944 | V34: 45944 | W34: 2239 | X34: 323151 | Y34: 301.86 | Z34: 59.95 | AA34: 24.15 | AB34: 385.96
A35: 45839 | B35: 52719 | C35: 6729 | D35: TKT | E35: GOL LINHAS AÉREAS | F35: =_xlfn.XLOOKUP(E35,DEPARA!A:A,DEPARA!C:C,"Verificar") -> PASSAGEM | G35: FIRSTLAB IND. IMP. E EXP. DE PROD. PARA LAB. LTDA | H35: 055-EQUIPE COMERCIAL 3 | I35: =_xlfn.XLOOKUP(fatoG1[[#This Row],[Centro de Custo]],dimCentroCusto[Centro_Custo],dimCentroCusto[Codigo_CentroCusto]) -> #N/A | J35: =fatoG1[[#This Row],[Desc. C. Custo Cliente]] -> 055-EQUIPE COMERCIAL 3 | L35: VISITA CLIENTES DA REGIÃO | N35: LUZ/MARCIO ARRUDA | O35: =_xlfn.XLOOKUP(N35,DEPARA!F:F,DEPARA!H:H,0) -> MARCIO ARRUDA LUZ | P35: =_xlfn.XLOOKUP(O35,dimColaborador!A:A,dimColaborador!B:B,0) -> 25745 | Q35: =_xlfn.XLOOKUP(O35,dimColaborador!A:A,dimColaborador!C:C,) -> GC - MÉDIO/GRANDE PORTE - SE/CO | R35: =_xlfn.XLOOKUP(O35,dimColaborador!A:A,dimColaborador!D:D) -> GRANDES CONTAS | S35: SAO JOSE DOS PINHAIS | T35: BSB/GIG | U35: 45947 | V35: 45947 | W35: 2140 | X35: 546648 | Y35: 319.9 | Z35: 30.95 | AA35: 25.59 | AB35: 376.44
A36: 45839 | B36: 52724 | C36: 6729 | D36: TKT | E36: TAM LINHAS AÉREAS | F36: =_xlfn.XLOOKUP(E36,DEPARA!A:A,DEPARA!C:C,"Verificar") -> PASSAGEM | G36: FIRSTLAB IND. IMP. E EXP. DE PROD. PARA LAB. LTDA | H36: 055-EQUIPE COMERCIAL 3 | I36: =_xlfn.XLOOKUP(fatoG1[[#This Row],[Centro de Custo]],dimCentroCusto[Centro_Custo],dimCentroCusto[Codigo_CentroCusto]) -> #N/A | J36: =fatoG1[[#This Row],[Desc. C. Custo Cliente]] -> 055-EQUIPE COMERCIAL 3 | L36: VISITA CLIENTES DA REGIÃO | N36: LUZ/MARCIO ARRUDA | O36: =_xlfn.XLOOKUP(N36,DEPARA!F:F,DEPARA!H:H,0) -> MARCIO ARRUDA LUZ | P36: =_xlfn.XLOOKUP(O36,dimColaborador!A:A,dimColaborador!B:B,0) -> 25745 | Q36: =_xlfn.XLOOKUP(O36,dimColaborador!A:A,dimColaborador!C:C,) -> GC - MÉDIO/GRANDE PORTE - SE/CO | R36: =_xlfn.XLOOKUP(O36,dimColaborador!A:A,dimColaborador!D:D) -> GRANDES CONTAS | S36: SAO JOSE DOS PINHAIS | T36: CGR*GRU/CGB | U36: 45953 | V36: 45953 | W36: 2239 | X36: 355175 | Y36: 426.56 | Z36: 36.67 | AA36: 34.12 | AB36: 497.35
A37: 45839 | B37: 52725 | C37: 6729 | D37: TKT | E37: TAM LINHAS AÉREAS | F37: =_xlfn.XLOOKUP(E37,DEPARA!A:A,DEPARA!C:C,"Verificar") -> PASSAGEM | G37: FIRSTLAB IND. IMP. E EXP. DE PROD. PARA LAB. LTDA | H37: 055-EQUIPE COMERCIAL 3 | I37: =_xlfn.XLOOKUP(fatoG1[[#This Row],[Centro de Custo]],dimCentroCusto[Centro_Custo],dimCentroCusto[Codigo_CentroCusto]) -> #N/A | J37: =fatoG1[[#This Row],[Desc. C. Custo Cliente]] -> 055-EQUIPE COMERCIAL 3 | L37: VISITA CLIENTES DA REGIÃO | N37: LUZ/MARCIO ARRUDA | O37: =_xlfn.XLOOKUP(N37,DEPARA!F:F,DEPARA!H:H,0) -> MARCIO ARRUDA LUZ | P37: =_xlfn.XLOOKUP(O37,dimColaborador!A:A,dimColaborador!B:B,0) -> 25745 | Q37: =_xlfn.XLOOKUP(O37,dimColaborador!A:A,dimColaborador!C:C,) -> GC - MÉDIO/GRANDE PORTE - SE/CO | R37: =_xlfn.XLOOKUP(O37,dimColaborador!A:A,dimColaborador!D:D) -> GRANDES CONTAS | S37: SAO JOSE DOS PINHAIS | T37: GIG*BSB/CGR | U37: 45951 | V37: 45951 | W37: 2239 | X37: 355198 | Y37: 335.4 | Z37: 34.11 | AA37: 26.83 | AB37: 396.34
A38: 45839 | B38: 52726 | C38: 6729 | D38: TKT | E38: TAM LINHAS AÉREAS | F38: =_xlfn.XLOOKUP(E38,DEPARA!A:A,DEPARA!C:C,"Verificar") -> PASSAGEM | G38: FIRSTLAB IND. IMP. E EXP. DE PROD. PARA LAB. LTDA | H38: 055-EQUIPE COMERCIAL 3 | I38: =_xlfn.XLOOKUP(fatoG1[[#This Row],[Centro de Custo]],dimCentroCusto[Centro_Custo],dimCentroCusto[Codigo_CentroCusto]) -> #N/A | J38: =fatoG1[[#This Row],[Desc. C. Custo Cliente]] -> 055-EQUIPE COMERCIAL 3 | L38: VISITA CLIENTES DA REGIÃO | N38: LUZ/MARCIO ARRUDA | O38: =_xlfn.XLOOKUP(N38,DEPARA!F:F,DEPARA!H:H,0) -> MARCIO ARRUDA LUZ | P38: =_xlfn.XLOOKUP(O38,dimColaborador!A:A,dimColaborador!B:B,0) -> 25745 | Q38: =_xlfn.XLOOKUP(O38,dimColaborador!A:A,dimColaborador!C:C,) -> GC - MÉDIO/GRANDE PORTE - SE/CO | R38: =_xlfn.XLOOKUP(O38,dimColaborador!A:A,dimColaborador!D:D) -> GRANDES CONTAS | S38: SAO JOSE DOS PINHAIS | T38: CGB*GRU/GIG | U38: 45954 | V38: 45954 | W38: 2239 | X38: 355944 | Y38: 444.53 | Z38: 48.75 | AA38: 35.56 | AB38: 528.84
